2022-05-05 21:57:52,801 INFO    MainThread:21002 [internal.py:wandb_internal():90] W&B internal server running at pid: 21002, started at: 2022-05-05 21:57:52.801526
2022-05-05 21:57:52,804 DEBUG   SenderThread:21002 [sender.py:send():232] send: header
2022-05-05 21:57:52,805 DEBUG   SenderThread:21002 [sender.py:send():232] send: run
2022-05-05 21:57:52,806 INFO    WriterThread:21002 [datastore.py:open_for_write():75] open: /home/jledesmau/build-model-workflow-exercises/lesson-2-data-exploration-and-preparation/exercises/exercise_6/starter/wandb/run-20220505_215752-36p7sjbw/run-36p7sjbw.wandb
2022-05-05 21:58:22,397 DEBUG   HandlerThread:21002 [handler.py:handle_request():141] handle_request: shutdown
2022-05-05 21:58:22,398 INFO    HandlerThread:21002 [handler.py:finish():806] shutting down handler
2022-05-05 21:58:22,815 INFO    WriterThread:21002 [datastore.py:close():279] close: /home/jledesmau/build-model-workflow-exercises/lesson-2-data-exploration-and-preparation/exercises/exercise_6/starter/wandb/run-20220505_215752-36p7sjbw/run-36p7sjbw.wandb
2022-05-05 21:58:24,453 ERROR   SenderThread:21002 [internal_api.py:execute():143] 409 response executing GraphQL.
2022-05-05 21:58:24,454 ERROR   SenderThread:21002 [internal_api.py:execute():144] {"errors":[{"message":"Error 1062: Duplicate entry 'exercise_6-248190' for key 'ix_projects_name_entity_id'","path":["upsertBucket"]}],"data":{"upsertBucket":null}}
2022-05-05 21:58:24,454 ERROR   MainThread:21002 [internal.py:wandb_internal():165] Thread SenderThread:
Traceback (most recent call last):
  File "/home/jledesmau/miniconda3/envs/mlflow-3d3869f2c83bdf6f47063dd53da363493fa4210a/lib/python3.9/site-packages/wandb/apis/normalize.py", line 22, in wrapper
    return func(*args, **kwargs)
  File "/home/jledesmau/miniconda3/envs/mlflow-3d3869f2c83bdf6f47063dd53da363493fa4210a/lib/python3.9/site-packages/wandb/sdk/internal/internal_api.py", line 1319, in upsert_run
    response = self.gql(mutation, variable_values=variable_values, **kwargs)
  File "/home/jledesmau/miniconda3/envs/mlflow-3d3869f2c83bdf6f47063dd53da363493fa4210a/lib/python3.9/site-packages/wandb/sdk/lib/retry.py", line 102, in __call__
    result = self._call_fn(*args, **kwargs)
  File "/home/jledesmau/miniconda3/envs/mlflow-3d3869f2c83bdf6f47063dd53da363493fa4210a/lib/python3.9/site-packages/wandb/sdk/internal/internal_api.py", line 140, in execute
    return self.client.execute(*args, **kwargs)
  File "/home/jledesmau/miniconda3/envs/mlflow-3d3869f2c83bdf6f47063dd53da363493fa4210a/lib/python3.9/site-packages/wandb/vendor/gql-0.2.0/wandb_gql/client.py", line 52, in execute
    result = self._get_result(document, *args, **kwargs)
  File "/home/jledesmau/miniconda3/envs/mlflow-3d3869f2c83bdf6f47063dd53da363493fa4210a/lib/python3.9/site-packages/wandb/vendor/gql-0.2.0/wandb_gql/client.py", line 60, in _get_result
    return self.transport.execute(document, *args, **kwargs)
  File "/home/jledesmau/miniconda3/envs/mlflow-3d3869f2c83bdf6f47063dd53da363493fa4210a/lib/python3.9/site-packages/wandb/vendor/gql-0.2.0/wandb_gql/transport/requests.py", line 39, in execute
    request.raise_for_status()
  File "/home/jledesmau/miniconda3/envs/mlflow-3d3869f2c83bdf6f47063dd53da363493fa4210a/lib/python3.9/site-packages/requests/models.py", line 960, in raise_for_status
    raise HTTPError(http_error_msg, response=self)
requests.exceptions.HTTPError: 409 Client Error: Conflict for url: https://api.wandb.ai/graphql

During handling of the above exception, another exception occurred:

Traceback (most recent call last):
  File "/home/jledesmau/miniconda3/envs/mlflow-3d3869f2c83bdf6f47063dd53da363493fa4210a/lib/python3.9/site-packages/wandb/sdk/internal/internal_util.py", line 51, in run
    self._run()
  File "/home/jledesmau/miniconda3/envs/mlflow-3d3869f2c83bdf6f47063dd53da363493fa4210a/lib/python3.9/site-packages/wandb/sdk/internal/internal_util.py", line 102, in _run
    self._process(record)
  File "/home/jledesmau/miniconda3/envs/mlflow-3d3869f2c83bdf6f47063dd53da363493fa4210a/lib/python3.9/site-packages/wandb/sdk/internal/internal.py", line 310, in _process
    self._sm.send(record)
  File "/home/jledesmau/miniconda3/envs/mlflow-3d3869f2c83bdf6f47063dd53da363493fa4210a/lib/python3.9/site-packages/wandb/sdk/internal/sender.py", line 234, in send
    send_handler(record)
  File "/home/jledesmau/miniconda3/envs/mlflow-3d3869f2c83bdf6f47063dd53da363493fa4210a/lib/python3.9/site-packages/wandb/sdk/internal/sender.py", line 692, in send_run
    self._init_run(run, config_value_dict)
  File "/home/jledesmau/miniconda3/envs/mlflow-3d3869f2c83bdf6f47063dd53da363493fa4210a/lib/python3.9/site-packages/wandb/sdk/internal/sender.py", line 716, in _init_run
    server_run, inserted = self._api.upsert_run(
  File "/home/jledesmau/miniconda3/envs/mlflow-3d3869f2c83bdf6f47063dd53da363493fa4210a/lib/python3.9/site-packages/wandb/apis/normalize.py", line 24, in wrapper
    raise CommError(err.response, err)
wandb.errors.CommError: <Response [409]>
2022-05-05 21:58:26,466 INFO    MainThread:21002 [internal.py:handle_exit():80] Internal process exited
